<?xml version="1.0" ?>
<!-- =================================================================================== -->
<!-- |    This document was autogenerated by xacro from /home/twkim/ros2_ws/src/modular/models/urdf/colony_2.xacro | -->
<!-- |    EDITING THIS FILE BY HAND IS NOT RECOMMENDED                                 | -->
<!-- =================================================================================== -->
<robot name="colony">
  <!--
    module_macro.xacro
    Usage: <xacro:module_instance prefix="r1_" parent="colony_base" xyz="0.15 0 0" rpy="0 0 1.57079632679"/>
  -->
  <link name="colony_base"/>
  <!-- Attach module root to parent -->
  <joint name="r1_mount" type="fixed">
    <origin rpy="0 -1.5707963 1.5708" xyz="0.15 0 0"/>
    <parent link="colony_base"/>
    <child link="r1_main_body_link"/>
  </joint>
  <!-- Main Body -->
  <link name="r1_main_body_link">
    <inertial>
      <origin rpy="0 0 0" xyz="0 0.003263 -0.024012"/>
      <mass value="0.0508654"/>
      <inertia ixx="3.2369E-05" ixy="-5.1865E-08" ixz="6.2298E-08" iyy="3.8892E-05" iyz="1.5562E-06" izz="3.8330E-05"/>
    </inertial>
    <visual>
      <origin rpy="0 0 0" xyz="0 0 0"/>
      <geometry>
        <mesh filename="meshes/main_body.STL"/>
      </geometry>
      <material name="r1_grey">
        <color rgba=".1 .1 .1 1"/>
      </material>
    </visual>
    <collision>
      <origin rpy="0 0 0" xyz="0 0 0"/>
      <geometry>
        <mesh filename="meshes/main_body.STL"/>
      </geometry>
    </collision>
  </link>
  <!-- Cap (fixed) -->
  <link name="r1_cap_link">
    <inertial>
      <origin rpy="0 0 0" xyz="0 0 0.002584"/>
      <mass value="0.0207453"/>
      <inertia ixx="5.2686E-06" ixy="2.2073E-12" ixz="-4.2054E-12" iyy="5.8008E-06" iyz="8.3798E-12" izz="1.0095E-05"/>
    </inertial>
    <visual>
      <origin rpy="0 0 0" xyz="0 0 0"/>
      <geometry>
        <mesh filename="meshes/cap.STL"/>
      </geometry>
      <material name="r1_grey"/>
    </visual>
    <collision>
      <origin rpy="0 0 0" xyz="0 0 0"/>
      <geometry>
        <mesh filename="meshes/cap.STL"/>
      </geometry>
    </collision>
  </link>
  <!-- Motor (fixed) -->
  <link name="r1_motor_link">
    <inertial>
      <origin rpy="0 0 0" xyz="0.000583 0.013451 0"/>
      <mass value="0.0180991"/>
      <inertia ixx="1.7385E-06" ixy="-6.0293E-09" ixz="-2.8041E-10" iyy="1.8742E-06" iyz="-3.9561E-11" izz="2.9658E-06"/>
    </inertial>
    <visual>
      <origin rpy="0 0 0" xyz="0 0 0"/>
      <geometry>
        <mesh filename="meshes/motor.STL"/>
      </geometry>
      <material name="r1_red">
        <color rgba=".5 .1 .1 1"/>
      </material>
    </visual>
    <collision>
      <origin rpy="0 0 0" xyz="0 0 0"/>
      <geometry>
        <mesh filename="meshes/motor.STL"/>
      </geometry>
    </collision>
  </link>
  <joint name="r1_main_body_to_cap" type="fixed">
    <origin rpy="0 0 0" xyz="0 0 0.001"/>
    <parent link="r1_main_body_link"/>
    <child link="r1_cap_link"/>
  </joint>
  <joint name="r1_main_body_to_motor" type="fixed">
    <origin rpy="1.57079632679 0 0" xyz="0 -0.017 -0.055"/>
    <parent link="r1_main_body_link"/>
    <child link="r1_motor_link"/>
  </joint>
  <!-- Motor paddle (revolute hinge) -->
  <link name="r1_motor_paddle_link">
    <inertial>
      <origin rpy="0 0 0" xyz="-0.00442 -0.000212 0"/>
      <mass value="0.000425108"/>
      <inertia ixx="2.9604E-09" ixy="1.1351E-10" ixz="-4.1107E-26" iyy="1.4476E-08" iyz="5.9011E-26" izz="1.7153E-08"/>
    </inertial>
    <visual>
      <origin rpy="0 0 0" xyz="0 0 0"/>
      <geometry>
        <mesh filename="meshes/motor_paddle.STL"/>
      </geometry>
      <material name="r1_grey"/>
    </visual>
    <collision>
      <origin rpy="0 0 0" xyz="0 0 0"/>
      <geometry>
        <mesh filename="meshes/motor_paddle.STL"/>
      </geometry>
    </collision>
  </link>
  <joint name="r1_motor_hinge" type="revolute">
    <origin rpy="1.57079632679 0 0" xyz="0.008 0.035 0"/>
    <axis xyz="0 0 1"/>
    <limit effort="1.0" lower="-0.7854" upper="0.7854" velocity="10.0"/>
    <parent link="r1_motor_link"/>
    <child link="r1_motor_paddle_link"/>
    <dynamics damping="1e-1"/>
  </joint>
  <!-- flA, flB (fixed) -->
  <link name="r1_flA_link">
    <inertial>
      <origin rpy="0 0 0" xyz="0.001618 0.001988 -0.000278"/>
      <mass value="0.0175588"/>
      <inertia ixx="4.1751E-08" ixy="1.0291E-08" ixz="2.1462E-09" iyy="1.2538E-07" iyz="1.0233E-09" izz="1.6320E-07"/>
    </inertial>
    <visual>
      <origin rpy="0 0 0" xyz="0 0 0"/>
      <geometry>
        <mesh filename="meshes/flA.STL"/>
      </geometry>
      <material name="r1_grey"/>
    </visual>
    <collision>
      <origin rpy="0 0 0" xyz="0 0 0"/>
      <geometry>
        <mesh filename="meshes/flA.STL"/>
      </geometry>
    </collision>
  </link>
  <link name="r1_flB_link">
    <inertial>
      <origin rpy="0 0 0" xyz="0.001618 0.001988 0.000278"/>
      <mass value="0.017588"/>
      <inertia ixx="4.1751E-08" ixy="1.0291E-08" ixz="-2.1462E-09" iyy="1.2538E-07" iyz="-1.0233E-09" izz="1.6320E-07"/>
    </inertial>
    <visual>
      <origin rpy="0 0 0" xyz="0 0 0"/>
      <geometry>
        <mesh filename="meshes/flB.STL"/>
      </geometry>
      <material name="r1_grey"/>
    </visual>
    <collision>
      <origin rpy="0 0 0" xyz="0 0 0"/>
      <geometry>
        <mesh filename="meshes/flB.STL"/>
      </geometry>
    </collision>
  </link>
  <joint name="r1_motor_paddle_to_flA" type="fixed">
    <origin rpy="0 0 0" xyz="-0.025 0 0.003"/>
    <parent link="r1_motor_paddle_link"/>
    <child link="r1_flA_link"/>
  </joint>
  <joint name="r1_motor_paddle_to_flB" type="fixed">
    <origin rpy="0 0 0" xyz="-0.025 0 -0.003"/>
    <parent link="r1_motor_paddle_link"/>
    <child link="r1_flB_link"/>
  </joint>
  <!-- Paddle (revolute hinge) -->
  <link name="r1_paddle_link">
    <inertial>
      <origin rpy="0 0 0" xyz="0.001281 0.029867 0"/>
      <mass value="0.00849369"/>
      <inertia ixx="4.2957E-06" ixy="3.0329E-08" ixz="1.9701E-22" iyy="1.9992E-06" iyz="-3.8433E-22" izz="2.7663E-06"/>
    </inertial>
    <visual>
      <origin rpy="0 0 0" xyz="0 0 0"/>
      <geometry>
        <mesh filename="meshes/paddle.STL"/>
      </geometry>
      <material name="r1_mint">
        <color rgba="0.02 0.5 0.46 1"/>
      </material>
    </visual>
    <collision>
      <origin rpy="0 0 0" xyz="0 0 0"/>
      <geometry>
        <mesh filename="meshes/paddle.STL"/>
      </geometry>
    </collision>
  </link>
  <joint name="r1_paddle_hinge" type="revolute">
    <origin rpy="0 0 1.96349539694" xyz="-0.0335 0.0015 0"/>
    <axis xyz="0 0 1"/>
    <limit effort="1.0" lower="-0.3927" upper="0.3927" velocity="10.0"/>
    <parent link="r1_motor_paddle_link"/>
    <child link="r1_paddle_link"/>
    <dynamics damping="1e-1"/>
  </joint>
  <!-- Attach module root to parent -->
  <joint name="r2_mount" type="fixed">
    <origin rpy="0 -1.5707963 4.71239" xyz="-0.15 1.83697e-17 0"/>
    <parent link="colony_base"/>
    <child link="r2_main_body_link"/>
  </joint>
  <!-- Main Body -->
  <link name="r2_main_body_link">
    <inertial>
      <origin rpy="0 0 0" xyz="0 0.003263 -0.024012"/>
      <mass value="0.0508654"/>
      <inertia ixx="3.2369E-05" ixy="-5.1865E-08" ixz="6.2298E-08" iyy="3.8892E-05" iyz="1.5562E-06" izz="3.8330E-05"/>
    </inertial>
    <visual>
      <origin rpy="0 0 0" xyz="0 0 0"/>
      <geometry>
        <mesh filename="meshes/main_body.STL"/>
      </geometry>
      <material name="r2_grey">
        <color rgba=".1 .1 .1 1"/>
      </material>
    </visual>
    <collision>
      <origin rpy="0 0 0" xyz="0 0 0"/>
      <geometry>
        <mesh filename="meshes/main_body.STL"/>
      </geometry>
    </collision>
  </link>
  <!-- Cap (fixed) -->
  <link name="r2_cap_link">
    <inertial>
      <origin rpy="0 0 0" xyz="0 0 0.002584"/>
      <mass value="0.0207453"/>
      <inertia ixx="5.2686E-06" ixy="2.2073E-12" ixz="-4.2054E-12" iyy="5.8008E-06" iyz="8.3798E-12" izz="1.0095E-05"/>
    </inertial>
    <visual>
      <origin rpy="0 0 0" xyz="0 0 0"/>
      <geometry>
        <mesh filename="meshes/cap.STL"/>
      </geometry>
      <material name="r2_grey"/>
    </visual>
    <collision>
      <origin rpy="0 0 0" xyz="0 0 0"/>
      <geometry>
        <mesh filename="meshes/cap.STL"/>
      </geometry>
    </collision>
  </link>
  <!-- Motor (fixed) -->
  <link name="r2_motor_link">
    <inertial>
      <origin rpy="0 0 0" xyz="0.000583 0.013451 0"/>
      <mass value="0.0180991"/>
      <inertia ixx="1.7385E-06" ixy="-6.0293E-09" ixz="-2.8041E-10" iyy="1.8742E-06" iyz="-3.9561E-11" izz="2.9658E-06"/>
    </inertial>
    <visual>
      <origin rpy="0 0 0" xyz="0 0 0"/>
      <geometry>
        <mesh filename="meshes/motor.STL"/>
      </geometry>
      <material name="r2_red">
        <color rgba=".5 .1 .1 1"/>
      </material>
    </visual>
    <collision>
      <origin rpy="0 0 0" xyz="0 0 0"/>
      <geometry>
        <mesh filename="meshes/motor.STL"/>
      </geometry>
    </collision>
  </link>
  <joint name="r2_main_body_to_cap" type="fixed">
    <origin rpy="0 0 0" xyz="0 0 0.001"/>
    <parent link="r2_main_body_link"/>
    <child link="r2_cap_link"/>
  </joint>
  <joint name="r2_main_body_to_motor" type="fixed">
    <origin rpy="1.57079632679 0 0" xyz="0 -0.017 -0.055"/>
    <parent link="r2_main_body_link"/>
    <child link="r2_motor_link"/>
  </joint>
  <!-- Motor paddle (revolute hinge) -->
  <link name="r2_motor_paddle_link">
    <inertial>
      <origin rpy="0 0 0" xyz="-0.00442 -0.000212 0"/>
      <mass value="0.000425108"/>
      <inertia ixx="2.9604E-09" ixy="1.1351E-10" ixz="-4.1107E-26" iyy="1.4476E-08" iyz="5.9011E-26" izz="1.7153E-08"/>
    </inertial>
    <visual>
      <origin rpy="0 0 0" xyz="0 0 0"/>
      <geometry>
        <mesh filename="meshes/motor_paddle.STL"/>
      </geometry>
      <material name="r2_grey"/>
    </visual>
    <collision>
      <origin rpy="0 0 0" xyz="0 0 0"/>
      <geometry>
        <mesh filename="meshes/motor_paddle.STL"/>
      </geometry>
    </collision>
  </link>
  <joint name="r2_motor_hinge" type="revolute">
    <origin rpy="1.57079632679 0 0" xyz="0.008 0.035 0"/>
    <axis xyz="0 0 1"/>
    <limit effort="1.0" lower="-0.7854" upper="0.7854" velocity="10.0"/>
    <parent link="r2_motor_link"/>
    <child link="r2_motor_paddle_link"/>
    <dynamics damping="1e-1"/>
  </joint>
  <!-- flA, flB (fixed) -->
  <link name="r2_flA_link">
    <inertial>
      <origin rpy="0 0 0" xyz="0.001618 0.001988 -0.000278"/>
      <mass value="0.0175588"/>
      <inertia ixx="4.1751E-08" ixy="1.0291E-08" ixz="2.1462E-09" iyy="1.2538E-07" iyz="1.0233E-09" izz="1.6320E-07"/>
    </inertial>
    <visual>
      <origin rpy="0 0 0" xyz="0 0 0"/>
      <geometry>
        <mesh filename="meshes/flA.STL"/>
      </geometry>
      <material name="r2_grey"/>
    </visual>
    <collision>
      <origin rpy="0 0 0" xyz="0 0 0"/>
      <geometry>
        <mesh filename="meshes/flA.STL"/>
      </geometry>
    </collision>
  </link>
  <link name="r2_flB_link">
    <inertial>
      <origin rpy="0 0 0" xyz="0.001618 0.001988 0.000278"/>
      <mass value="0.017588"/>
      <inertia ixx="4.1751E-08" ixy="1.0291E-08" ixz="-2.1462E-09" iyy="1.2538E-07" iyz="-1.0233E-09" izz="1.6320E-07"/>
    </inertial>
    <visual>
      <origin rpy="0 0 0" xyz="0 0 0"/>
      <geometry>
        <mesh filename="meshes/flB.STL"/>
      </geometry>
      <material name="r2_grey"/>
    </visual>
    <collision>
      <origin rpy="0 0 0" xyz="0 0 0"/>
      <geometry>
        <mesh filename="meshes/flB.STL"/>
      </geometry>
    </collision>
  </link>
  <joint name="r2_motor_paddle_to_flA" type="fixed">
    <origin rpy="0 0 0" xyz="-0.025 0 0.003"/>
    <parent link="r2_motor_paddle_link"/>
    <child link="r2_flA_link"/>
  </joint>
  <joint name="r2_motor_paddle_to_flB" type="fixed">
    <origin rpy="0 0 0" xyz="-0.025 0 -0.003"/>
    <parent link="r2_motor_paddle_link"/>
    <child link="r2_flB_link"/>
  </joint>
  <!-- Paddle (revolute hinge) -->
  <link name="r2_paddle_link">
    <inertial>
      <origin rpy="0 0 0" xyz="0.001281 0.029867 0"/>
      <mass value="0.00849369"/>
      <inertia ixx="4.2957E-06" ixy="3.0329E-08" ixz="1.9701E-22" iyy="1.9992E-06" iyz="-3.8433E-22" izz="2.7663E-06"/>
    </inertial>
    <visual>
      <origin rpy="0 0 0" xyz="0 0 0"/>
      <geometry>
        <mesh filename="meshes/paddle.STL"/>
      </geometry>
      <material name="r2_mint">
        <color rgba="0.02 0.5 0.46 1"/>
      </material>
    </visual>
    <collision>
      <origin rpy="0 0 0" xyz="0 0 0"/>
      <geometry>
        <mesh filename="meshes/paddle.STL"/>
      </geometry>
    </collision>
  </link>
  <joint name="r2_paddle_hinge" type="revolute">
    <origin rpy="0 0 1.96349539694" xyz="-0.0335 0.0015 0"/>
    <axis xyz="0 0 1"/>
    <limit effort="1.0" lower="-0.3927" upper="0.3927" velocity="10.0"/>
    <parent link="r2_motor_paddle_link"/>
    <child link="r2_paddle_link"/>
    <dynamics damping="1e-1"/>
  </joint>
</robot>
